Workbook

Sheet Start
A1: Welcome to the tour. Instructions for screen readers: In just 10 steps, you'll be up and running with Excel, the world's most popular spreadsheet app. There are 11 more sheets in this tour. The instructions for each sheet start in cell A1, and each subsequent step is in cell A2, A3, and so on. The instructions will indicate which cells to navigate to for use of a feature, or further reading. To start, press CTRL+PAGE DOWN.
A2: Case Study 1
A3: Putting taught concepts to good use.
A4: Go back to top by pressing CTRL+HOME. To start the tour, press CTRL+PAGE DOWN.

Sheet Sheet1
A3: Age Range | B3: Employee | D3: Age Range | E3: Age | F3: Sacked | K3: Country | L3: Count of employee | Q3: Full Name | R3: sacked | S3: Sum of Age | V3: Paid | W3: Count of Paid | Z3: UnPaid | AA3: Count of Unpaid | AD3: Payment Status | AE3: Sum of Salary
A4: 40-50 | B4: 32 | D4: Paid | E4: 2646 | F4: 859 | K4: USA | L4: 74 | Q4: Suzanne Connor | R4: 19 | S4: 37 | W4: 48 | AA4: 54 | AD4: Paid | AE4: 11471
A5: 50-60 | B5: 31 | D5: Alan Evan | E5: 41 | F5: 16 | K5: Canada | L5: 19 | Q5: Omar Amanda | R5: 18 | S5: 38 | V5: Jon Syed | W5: 1 | Z5: Jorge Catherine | AA5: 1 | AD5: Unpaid | AE5: 10430
A6: 60-70 | B6: 22 | D6: Alejandro Fernando | E6: 39 | F6: 16 | K6: Australia | L6: 7 | Q6: Karen Kim | R6: 18 | S6: 51 | V6: Karen Kim | W6: 1 | Z6: Kelvin Kim | AA6: 1 | AD6: Grand Total | AE6: 21901
A7: 70-80 | B7: 15 | D7: Alisha Frances | E7: 58 | F7: 15 | K7: New Zealand | L7: 2 | Q7: Christy Jack | R7: 17 | S7: 69 | V7: Kelli Kim | W7: 1 | Z7: Kristen Hazem | AA7: 1
A8: 80-90 | B8: 2 | D8: Bianca Hunter | E8: 35 | F8: 16 | K8: Grand Total | L8: 102 | Q8: Cedric Isaiah | R8: 17 | S8: 69 | V8: Krystal Sam | W8: 1 | Z8: Lacey Humberto | AA8: 1
A9: Grand Total | B9: 102 | D9: Brittney Isaac | E9: 49 | F9: 16 | Q9: Louis Aaron | R9: 17 | S9: 66 | V9: Laura Gustavo | W9: 1 | Z9: Leah Pilar | AA9: 1
D10: Cedric Isaiah | E10: 69 | F10: 17 | Q10: Clarence Jackson | R10: 17 | S10: 69 | V10: Louis Aaron | W10: 1 | Z10: Lisa Pilar | AA10: 1 | AC10: Payment Status | AD10: Sum of Tax
D11: Christy Jack | E11: 69 | F11: 17 | Q11: Franklin Jordan | R11: 17 | S11: 69 | V11: Mandy Adam | W11: 1 | Z11: Margaret Alex | AA11: 1 | AC11: 12 | AD11: 122
D12: Colin James | E12: 69 | F12: 17 | K12: Country | N12: Hire Months | O12: Count of Employee | Q12: Jorge Catherine | R12: 17 | S12: 54 | V12: Micah Allison | W12: 1 | Z12: Martha Alexandra | AA12: 1 | AC12: 70 | AD12: 122
D13: Crystal Jay | E13: 39 | F13: 15 | K13: 40-50 | N13: January | O13: 31 | Q13: Kelli Kim | R13: 17 | S13: 50 | V13: Randy Angel | W13: 1 | Z13: Omar Amanda | AA13: 1 | AC13: 62 | AD13: 122
D14: Dennis Jennifer | E14: 54 | F14: 16 | K14: Alejandro Fernando | N14: February | O14: 28 | Q14: Clayton Jada | R14: 17 | S14: 69 | V14: Roger Bailey | W14: 1 | Z14: Rafael Amber | AA14: 1 | AC14: 57 | AD14: 72
D15: Edwin Jeremy | E15: 39 | F15: 16 | K15: Barbara Haley | N15: March | O15: 10 | Q15: Kristen Hazem | R15: 17 | S15: 66 | V15: Rosa Ben | W15: 1 | Z15: Ramon Andrea | AA15: 1 | AC15: 36 | AD15: 48
D16: Erica Jesse | E16: 46 | F16: 16 | K16: Bianca Hunter | N16: May | O16: 1 | Q16: Colin James | R16: 17 | S16: 69 | V16: Sandra Blake | W16: 1 | Z16: Shannon Carla | AA16: 1 | AC16: 25 | AD16: 48
D17: Ernest Jonathan | E17: 48 | F17: 16 | K17: Brent Ian | N17: June | O17: 1 | Q17: Micah Allison | R17: 17 | S17: 50 | V17: Susan Chloe | W17: 1 | Z17: Stacey Carlos | AA17: 1 | AC17: 33 | AD17: 48
D18: Franklin Jordan | E18: 69 | F18: 17 | K18: Candice Isabella | N18: November | O18: 1 | Q18: Colleen Jason | R18: 17 | S18: 69 | V18: Tiffany Dalton | W18: 1 | Z18: Steve Charles | AA18: 1 | AC18: 46 | AD18: 48
D19: Gilbert Jose | E19: 70 | F19: 15 | K19: Crystal Jay | N19: December | O19: 30 | Q19: Amy Gabriella | R19: 17 | S19: 69 | V19: Trisha Devin | W19: 1 | Z19: Suzanne Connor | AA19: 1 | AC19: 26 | AD19: 45
D20: Jaclyn Katelyn | E20: 55 | F20: 15 | K20: Dawn Jenna | N20: Grand Total | O20: 102 | Q20: Susan Chloe | R20: 17 | S20: 69 | V20: Valerie Eduardo | W20: 1 | Z20: Tamara Courtney | AA20: 1 | AC20: 87 | AD20: 38
D21: Jamie Kaylee | E21: 54 | F21: 15 | K21: Edwin Jeremy | Q21: Damien Jay | R21: 17 | S21: 69 | V21: Alan Evan | W21: 1 | Z21: Vincent Edward | AA21: 1 | AC21: 72 | AD21: 38
D22: Jenny Kyle | E22: 40 | F22: 16 | K22: Eugene Jordan | Q22: Kelvin Kim | R22: 17 | S22: 73 | V22: Alejandro Fernando | W22: 1 | Z22: Warren Elijah | AA22: 1 | AC22: 67 | AD22: 38
D23: Jessie Logan | E23: 36 | F23: 16 | K23: Jeffery Kevin | Q23: Roger Bailey | R23: 16 | S23: 39 | V23: Alisha Frances | W23: 1 | Z23: Wesley Eric | AA23: 1 | AC23: 18 | AD23: 38
D24: Jon Lucas | E24: 48 | F24: 16 | K24: Jenny Kyle | Q24: Trisha Devin | R24: 16 | S24: 39 | V24: Bianca Hunter | W24: 1 | Z24: Alvin Gabriel | AA24: 1 | AC24: 81 | AD24: 38
D25: Jon Syed | E25: 56 | F25: 16 | K25: Jessie Logan | Q25: Susan Sydney | R25: 16 | S25: 53 | V25: Brittney Isaac | W25: 1 | Z25: Amy Gabriella | AA25: 1 | AC25: 39 | AD25: 38
D26: Karen Kim | E26: 51 | F26: 18 | K26: Karen Luke | Q26: Erica Jesse | R26: 16 | S26: 46 | V26: Cedric Isaiah | W26: 1 | Z26: Arturo Gabrielle | AA26: 1 | AC26: 66 | AD26: 38
D27: Kelli Kim | E27: 50 | F27: 17 | K27: Kelvin Marcus | Q27: Edwin Jeremy | R27: 16 | S27: 39 | V27: Christy Jack | W27: 1 | Z27: Autumn Hailey | AA27: 1 | AC27: 94 | AD27: 38
D28: Kelvin Marcus | E28: 37 | F28: 16 | K28: Krystal Sam | Q28: Ernest Jonathan | R28: 16 | S28: 48 | V28: Colin James | W28: 1 | Z28: Barbara Haley | AA28: 1 | AC28: 17 | AD28: 38
D29: Krystal Maria | E29: 42 | F29: 16 | K29: Lacey Humberto | Q29: Stacey Carlos | R29: 16 | S29: 42 | V29: Crystal Jay | W29: 1 | Z29: Brent Ian | AA29: 1 | AC29: 68 | AD29: 38
D30: Krystal Sam | E30: 38 | F30: 16 | K30: Lacey Mary | Q30: Eugene Jordan | R30: 16 | S30: 36 | V30: Dennis Jennifer | W30: 1 | Z30: Candice Isabella | AA30: 1 | AC30: 97 | AD30: 38
D31: Lacey Mary | E31: 38 | F31: 16 | K31: Mandy Adam | Q31: Tamara Wyatt | R31: 16 | S31: 35 | V31: Edwin Jeremy | W31: 1 | Z31: Clarence Jackson | AA31: 1 | AC31: 74 | AD31: 38
D32: Laura Gustavo | E32: 46 | F32: 16 | K32: Omar Amanda | Q32: Candice Isabella | R32: 16 | S32: 37 | V32: Erica Jesse | W32: 1 | Z32: Clayton Jada | AA32: 1 | AC32: 21 | AD32: 38
... D53: Todd Ronald | E53: 47 | F53: 16 | K53: Jon Lucas | Q53: Rosa Ben | R53: 16 | S53: 38 | V53: Suzanne Thomas | W53: 1 | Z53: Grand Total | AA53: 102 | AC53: 101 | AD53: 22
D54: Trisha Devin | E54: 39 | F54: 16 | K54: Jorge Luis | Q54: Autumn Hailey | R54: 16 | S54: 41 | V54: Tiffany Xavier | W54: 1 | AC54: 85 | AD54: 22
D55: Valerie Eduardo | E55: 48 | F55: 16 | K55: Kelli Kim | Q55: Shannon Carla | R55: 16 | S55: 46 | V55: Todd Ronald | W55: 1 | AC55: 47 | AD55: 22
D56: Valerie Osarumwense | E56: 46 | F56: 16 | K56: Kelli Mackenzie | Q56: Kelli Mackenzie | R56: 16 | S56: 43 | V56: Valerie Osarumwense | W56: 1 | AC56: 84 | AD56: 22
D57: Vincent Samuel | E57: 52 | F57: 16 | K57: Krystal Maria | Q57: Stacey Stephanie | R57: 16 | S57: 45 | V57: Vincent Samuel | W57: 1 | AC57: 51 | AD57: 22
D58: Wesley James | E58: 54 | F58: 16 | K58: Laura Gustavo | Q58: Willie Robert | R58: 16 | S58: 42 | V58: Wesley James | W58: 1 | AC58: 79 | AD58: 0
D59: Unpaid | E59: 2328 | F59: 762 | K59: Leah Pilar | Q59: Dawn Jenna | R59: 16 | S59: 37 | V59: Grand Total | W59: 102 | AC59: 95 | AD59: 0
D60: Alvin Gabriel | E60: 54 | F60: 15 | K60: Lisa Pilar | Q60: Kelvin Marcus | R60: 16 | S60: 37 | AC60: 42 | AD60: 0
D61: Amy Gabriella | E61: 69 | F61: 17 | K61: Margaret Alex | Q61: Dennis Jennifer | R61: 16 | S61: 54 | AC61: 11 | AD61: 0
D62: Arturo Gabrielle | E62: 52 | F62: 16 | K62: Micah Allison | Q62: Barbara Haley | R62: 16 | S62: 37 | AC62: 48 | AD62: 0
...

Sheet Dashboard

Sheet Staff Info
E1: HacMarine Dataset
A2: Staff ID | B2: Full Name | C2: First Name | D2: Last Name | E2: Address | F2: Country | G2: City | H2: State | I2: DoB | J2: Age | K2: Age Range | L2: Today's date | M2: MaritalStatus | N2: Gender | O2: Hire Date | P2: Hire Months | Q2: Work Experience | R2: Payment status | S2: Payment status 2 | T2: Paid | U2: Unpaid | V2: Salary | W2: Tax | X2: Tax Rate
A3: 1 | B3: =CONCATENATE(D3, " ",C3) -> Jon Syed | C3: Syed | D3: Jon | E3: 765 Kingway | F3: Canada | G3: Charlottetown | H3: PEI | I3: 25232 | J3: =ROUNDDOWN(YEARFRAC(I3,L3), 0) -> 56 | K3: =IF(J3<=30, "20-30",IF(J3<=40, "40-50",IF(J3<=50, "50-60",IF(J3<=60, "60-70",IF(J3<=70, "70-80",IF(J3<=80, "80-90")))))) -> 60-70 | L3: =TODAY() -> 45991 | M3: S | N3: M | O3: 39827 | P3: =TEXT(O3, "mmmm") -> January | Q3: =ROUNDDOWN(YEARFRAC(O3, L3),0) -> 16 | R3: 1 | S3: =IF(R3=1, "Paid","Unpaid" ) -> Paid | T3: =IF(S3="Paid",B3, " ") -> Jon Syed | U3: =IF(S3="Unpaid",B3, " ") | V3: =VLOOKUP(A3,'Staff Salary'!A2:B103,2) -> 120 | W3: =IF(AND(TRIM(N3) = "M",TRIM(F3) ="USA"),V3*X3,0) -> 0 | X3: 0.2
A4: 2 | B4: =CONCATENATE(D4, " ",C4) -> Jorge Catherine | C4: Catherine | D4: Jorge | E4: 234 E Cannon Ave. | F4: USA | G4: Saginaw | H4: MI | I4: 26146 | J4: =ROUNDDOWN(YEARFRAC(I4,L4), 0) -> 54 | K4: =IF(J4<=30, "20-30",IF(J4<=40, "40-50",IF(J4<=50, "50-60",IF(J4<=60, "60-70",IF(J4<=70, "70-80",IF(J4<=80, "80-90")))))) -> 60-70 | L4: =TODAY() -> 45991 | M4: S | N4: F | O4: 39478 | P4: =TEXT(O4, "mmmm") -> January | Q4: =ROUNDDOWN(YEARFRAC(O4, L4),0) -> 17 | R4: 0 | S4: =IF(R4=1, "Paid","Unpaid" ) -> Unpaid | T4: =IF(S4="Paid",B4, " ") | U4: =IF(S4="Unpaid",B4, " ") -> Jorge Catherine | V4: =VLOOKUP(A4,'Staff Salary'!A3:B104,2) -> 190 | W4: =IF(AND(TRIM(N4) = "M",TRIM(F4) ="USA"),V4*X4,0) -> 0 | X4: 0.2
A5: 3 | B5: =CONCATENATE(D5, " ",C5) -> Karen Kim | C5: Kim | D5: Karen | E5: 234 Heritage Ave. | F5: USA | G5: Midland | H5: MI | I5: 27345 | J5: =ROUNDDOWN(YEARFRAC(I5,L5), 0) -> 51 | K5: =IF(J5<=30, "20-30",IF(J5<=40, "40-50",IF(J5<=50, "50-60",IF(J5<=60, "60-70",IF(J5<=70, "70-80",IF(J5<=80, "80-90")))))) -> 60-70 | L5: =TODAY() -> 45991 | M5: M | N5: M | O5: 39397 | P5: =TEXT(O5, "mmmm") -> November | Q5: =ROUNDDOWN(YEARFRAC(O5, L5),0) -> 18 | R5: 1 | S5: =IF(R5=1, "Paid","Unpaid" ) -> Paid | T5: =IF(S5="Paid",B5, " ") -> Karen Kim | U5: =IF(S5="Unpaid",B5, " ") | V5: =VLOOKUP(A5,'Staff Salary'!A4:B105,2) -> 120 | W5: =IF(AND(TRIM(N5) = "M",TRIM(F5) ="USA"),V5*X5,0) -> 24 | X5: 0.2
A6: 4 | B6: =CONCATENATE(D6, " ",C6) -> Kelli Kim | C6: Kim | D6: Kelli | E6: 5678 S. 42nd Ave. | F6: USA | G6: Rockford | H6: IL | I6: 27386 | J6: =ROUNDDOWN(YEARFRAC(I6,L6), 0) -> 50 | K6: =IF(J6<=30, "20-30",IF(J6<=40, "40-50",IF(J6<=50, "50-60",IF(J6<=60, "60-70",IF(J6<=70, "70-80",IF(J6<=80, "80-90")))))) -> 50-60 | L6: =TODAY() -> 45991 | M6: S | N6: M | O6: 39421 | P6: =TEXT(O6, "mmmm") -> December | Q6: =ROUNDDOWN(YEARFRAC(O6, L6),0) -> 17 | R6: 1 | S6: =IF(R6=1, "Paid","Unpaid" ) -> Paid | T6: =IF(S6="Paid",B6, " ") -> Kelli Kim | U6: =IF(S6="Unpaid",B6, " ") | V6: =VLOOKUP(A6,'Staff Salary'!A5:B106,2) -> 190 | W6: =IF(AND(TRIM(N6) = "M",TRIM(F6) ="USA"),V6*X6,0) -> 38 | X6: 0.2
A7: 5 | B7: =CONCATENATE(D7, " ",C7) -> Kelvin Kim | C7: Kim | D7: Kelvin | E7: 123 Yeo | F7: Australia | G7: Melbourne | H7: VIC | I7: 19264 | J7: =ROUNDDOWN(YEARFRAC(I7,L7), 0) -> 73 | K7: =IF(J7<=30, "20-30",IF(J7<=40, "40-50",IF(J7<=50, "50-60",IF(J7<=60, "60-70",IF(J7<=70, "70-80",IF(J7<=80, "80-90")))))) -> 80-90 | L7: =TODAY() -> 45991 | M7: M | N7: F | O7: 39453 | P7: =TEXT(O7, "mmmm") -> January | Q7: =ROUNDDOWN(YEARFRAC(O7, L7),0) -> 17 | R7: 0 | S7: =IF(R7=1, "Paid","Unpaid" ) -> Unpaid | T7: =IF(S7="Paid",B7, " ") | U7: =IF(S7="Unpaid",B7, " ") -> Kelvin Kim | V7: =VLOOKUP(A7,'Staff Salary'!A6:B107,2) -> 610 | W7: =IF(AND(TRIM(N7) = "M",TRIM(F7) ="USA"),V7*X7,0) -> 0 | X7: 0.2
A8: 6 | B8: =CONCATENATE(D8, " ",C8) -> Kristen Hazem | C8: Hazem | D8: Kristen | E8: 12345 Redmond Rd | F8: USA | G8: Milwaukee | H8: WI | I8: 21620 | J8: =ROUNDDOWN(YEARFRAC(I8,L8), 0) -> 66 | K8: =IF(J8<=30, "20-30",IF(J8<=40, "40-50",IF(J8<=50, "50-60",IF(J8<=60, "60-70",IF(J8<=70, "70-80",IF(J8<=80, "80-90")))))) -> 70-80 | L8: =TODAY() -> 45991 | M8: M | N8: M | O8: 39471 | P8: =TEXT(O8, "mmmm") -> January | Q8: =ROUNDDOWN(YEARFRAC(O8, L8),0) -> 17 | R8: 0 | S8: =IF(R8=1, "Paid","Unpaid" ) -> Unpaid | T8: =IF(S8="Paid",B8, " ") | U8: =IF(S8="Unpaid",B8, " ") -> Kristen Hazem | V8: =VLOOKUP(A8,'Staff Salary'!A7:B108,2) -> 120 | W8: =IF(AND(TRIM(N8) = "M",TRIM(F8) ="USA"),V8*X8,0) -> 24 | X8: 0.2
A9: 7 | B9: =CONCATENATE(D9, " ",C9) -> Krystal Sam | C9: Sam | D9: Krystal | E9: 234 Hampton Village | F9: USA | G9: Springfield | H9: IL | I9: 31832 | J9: =ROUNDDOWN(YEARFRAC(I9,L9), 0) -> 38 | K9: =IF(J9<=30, "20-30",IF(J9<=40, "40-50",IF(J9<=50, "50-60",IF(J9<=60, "60-70",IF(J9<=70, "70-80",IF(J9<=80, "80-90")))))) -> 40-50 | L9: =TODAY() -> 45991 | M9: M | N9: M | O9: 39852 | P9: =TEXT(O9, "mmmm") -> February | Q9: =ROUNDDOWN(YEARFRAC(O9, L9),0) -> 16 | R9: 1 | S9: =IF(R9=1, "Paid","Unpaid" ) -> Paid | T9: =IF(S9="Paid",B9, " ") -> Krystal Sam | U9: =IF(S9="Unpaid",B9, " ") | V9: =VLOOKUP(A9,'Staff Salary'!A8:B109,2) -> 120 | W9: =IF(AND(TRIM(N9) = "M",TRIM(F9) ="USA"),V9*X9,0) -> 24 | X9: 0.2
A10: 8 | B10: =CONCATENATE(D10, " ",C10) -> Lacey Humberto | C10: Humberto | D10: Lacey | E10: 1234 Westown Road | F10: USA | G10: West Des Moines | H10: IA | I10: 31568 | J10: =ROUNDDOWN(YEARFRAC(I10,L10), 0) -> 39 | K10: =IF(J10<=30, "20-30",IF(J10<=40, "40-50",IF(J10<=50, "50-60",IF(J10<=60, "60-70",IF(J10<=70, "70-80",IF(J10<=80, "80-90")))))) -> 40-50 | L10: =TODAY() -> 45991 | M10: S | N10: F | O10: 39811 | P10: =TEXT(O10, "mmmm") -> December | Q10: =ROUNDDOWN(YEARFRAC(O10, L10),0) -> 16 | R10: 0 | S10: =IF(R10=1, "Paid","Unpaid" ) -> Unpaid | T10: =IF(S10="Paid",B10, " ") | U10: =IF(S10="Unpaid",B10, " ") -> Lacey Humberto | V10: =VLOOKUP(A10,'Staff Salary'!A9:B110,2) -> 360 | W10: =IF(AND(TRIM(N10) = "M",TRIM(F10) ="USA"),V10*X10,0) -> 0 | X10: 0.2
A11: 9 | B11: =CONCATENATE(D11, " ",C11) -> Laura Gustavo | C11: Gustavo | D11: Laura | E11: 4321 West Broadway | F11: Canada | G11: Montreal | H11: PQ | I11: 28876 | J11: =ROUNDDOWN(YEARFRAC(I11,L11), 0) -> 46 | K11: =IF(J11<=30, "20-30",IF(J11<=40, "40-50",IF(J11<=50, "50-60",IF(J11<=60, "60-70",IF(J11<=70, "70-80",IF(J11<=80, "80-90")))))) -> 50-60 | L11: =TODAY() -> 45991 | M11: M | N11: F | O11: 39829 | P11: =TEXT(O11, "mmmm") -> January | Q11: =ROUNDDOWN(YEARFRAC(O11, L11),0) -> 16 | R11: 1 | S11: =IF(R11=1, "Paid","Unpaid" ) -> Paid | T11: =IF(S11="Paid",B11, " ") -> Laura Gustavo | U11: =IF(S11="Unpaid",B11, " ") | V11: =VLOOKUP(A11,'Staff Salary'!A10:B111,2) -> 190 | W11: =IF(AND(TRIM(N11) = "M",TRIM(F11) ="USA"),V11*X11,0) -> 0 | X11: 0.2
A12: 10 | B12: =CONCATENATE(D12, " ",C12) -> Leah Pilar | C12: Pilar | D12: Leah | E12: City 123 | F12: Australia | G12: Sydney | H12: NSW | I12: 31016 | J12: =ROUNDDOWN(YEARFRAC(I12,L12), 0) -> 41 | K12: =IF(J12<=30, "20-30",IF(J12<=40, "40-50",IF(J12<=50, "50-60",IF(J12<=60, "60-70",IF(J12<=70, "70-80",IF(J12<=80, "80-90")))))) -> 50-60 | L12: =TODAY() -> 45991 | M12: M | N12: M | O12: 39936 | P12: =TEXT(O12, "mmmm") -> May | Q12: =ROUNDDOWN(YEARFRAC(O12, L12),0) -> 16 | R12: 0 | S12: =IF(R12=1, "Paid","Unpaid" ) -> Unpaid | T12: =IF(S12="Paid",B12, " ") | U12: =IF(S12="Unpaid",B12, " ") -> Leah Pilar | V12: =VLOOKUP(A12,'Staff Salary'!A11:B112,2) -> 190 | W12: =IF(AND(TRIM(N12) = "M",TRIM(F12) ="USA"),V12*X12,0) -> 0 | X12: 0.2
A13: 11 | B13: =CONCATENATE(D13, " ",C13) -> Lisa Pilar | C13: Pilar | D13: Lisa | E13: 987 Portar Street | F13: New Zealand | G13: Auckland | I13: 28507 | J13: =ROUNDDOWN(YEARFRAC(I13,L13), 0) -> 47 | K13: =IF(J13<=30, "20-30",IF(J13<=40, "40-50",IF(J13<=50, "50-60",IF(J13<=60, "60-70",IF(J13<=70, "70-80",IF(J13<=80, "80-90")))))) -> 50-60 | L13: =TODAY() -> 45991 | M13: S | N13: M | O13: 40517 | P13: =TEXT(O13, "mmmm") -> December | Q13: =ROUNDDOWN(YEARFRAC(O13, L13),0) -> 14 | R13: 0 | S13: =IF(R13=1, "Paid","Unpaid" ) -> Unpaid | T13: =IF(S13="Paid",B13, " ") | U13: =IF(S13="Unpaid",B13, " ") -> Lisa Pilar | V13: =VLOOKUP(A13,'Staff Salary'!A12:B113,2) -> 190 | W13: =IF(AND(TRIM(N13) = "M",TRIM(F13) ="USA"),V13*X13,0) -> 0 | X13: 0.2
A14: 12 | B14: =CONCATENATE(D14, " ",C14) -> Louis Aaron | C14: Aaron | D14: Louis | E14: 8765 58th Street West | F14: USA | G14: St. Louis | H14: MO | I14: 21760 | J14: =ROUNDDOWN(YEARFRAC(I14,L14), 0) -> 66 | K14: =IF(J14<=30, "20-30",IF(J14<=40, "40-50",IF(J14<=50, "50-60",IF(J14<=60, "60-70",IF(J14<=70, "70-80",IF(J14<=80, "80-90")))))) -> 70-80 | L14: =TODAY() -> 45991 | M14: M | N14: M | O14: 39427 | P14: =TEXT(O14, "mmmm") -> December | Q14: =ROUNDDOWN(YEARFRAC(O14, L14),0) -> 17 | R14: 1 | S14: =IF(R14=1, "Paid","Unpaid" ) -> Paid | T14: =IF(S14="Paid",B14, " ") -> Louis Aaron | U14: =IF(S14="Unpaid",B14, " ") | V14: =VLOOKUP(A14,'Staff Salary'!A13:B114,2) -> 610 | W14: =IF(AND(TRIM(N14) = "M",TRIM(F14) ="USA"),V14*X14,0) -> 122 | X14: 0.2
A15: 13 | B15: =CONCATENATE(D15, " ",C15) -> Mandy Adam | C15: Adam | D15: Mandy | E15: 987 Union Circle | F15: USA | G15: Lockport | H15: IL | I15: 32656 | J15: =ROUNDDOWN(YEARFRAC(I15,L15), 0) -> 36 | K15: =IF(J15<=30, "20-30",IF(J15<=40, "40-50",IF(J15<=50, "50-60",IF(J15<=60, "60-70",IF(J15<=70, "70-80",IF(J15<=80, "80-90")))))) -> 40-50 | L15: =TODAY() -> 45991 | M15: M | N15: F | O15: 40535 | P15: =TEXT(O15, "mmmm") -> December | Q15: =ROUNDDOWN(YEARFRAC(O15, L15),0) -> 14 | R15: 1 | S15: =IF(R15=1, "Paid","Unpaid" ) -> Paid | T15: =IF(S15="Paid",B15, " ") -> Mandy Adam | U15: =IF(S15="Unpaid",B15, " ") | V15: =VLOOKUP(A15,'Staff Salary'!A14:B115,2) -> 110 | W15: =IF(AND(TRIM(N15) = "M",TRIM(F15) ="USA"),V15*X15,0) -> 0 | X15: 0.2
A16: 14 | B16: =CONCATENATE(D16, " ",C16) -> Margaret Alex | C16: Alex | D16: Margaret | E16: 678 W Orange Ave | F16: USA | G16: Lafayette | H16: IN | I16: 29022 | J16: =ROUNDDOWN(YEARFRAC(I16,L16), 0) -> 46 | K16: =IF(J16<=30, "20-30",IF(J16<=40, "40-50",IF(J16<=50, "50-60",IF(J16<=60, "60-70",IF(J16<=70, "70-80",IF(J16<=80, "80-90")))))) -> 50-60 | L16: =TODAY() -> 45991 | M16: S | N16: M | O16: 40542 | P16: =TEXT(O16, "mmmm") -> December | Q16: =ROUNDDOWN(YEARFRAC(O16, L16),0) -> 14 | R16: 0 | S16: =IF(R16=1, "Paid","Unpaid" ) -> Unpaid | T16: =IF(S16="Paid",B16, " ") | U16: =IF(S16="Unpaid",B16, " ") -> Margaret Alex | V16: =VLOOKUP(A16,'Staff Salary'!A15:B116,2) -> 120 | W16: =IF(AND(TRIM(N16) = "M",TRIM(F16) ="USA"),V16*X16,0) -> 24 | X16: 0.2
A17: 15 | B17: =CONCATENATE(D17, " ",C17) -> Martha Alexandra | C17: Alexandra | D17: Martha | E17: P.O. Box 1234 | F17: USA | G17: Wichita | H17: KS | I17: 22403 | J17: =ROUNDDOWN(YEARFRAC(I17,L17), 0) -> 64 | K17: =IF(J17<=30, "20-30",IF(J17<=40, "40-50",IF(J17<=50, "50-60",IF(J17<=60, "60-70",IF(J17<=70, "70-80",IF(J17<=80, "80-90")))))) -> 70-80 | L17: =TODAY() -> 45991 | M17: M | N17: F | O17: 40561 | P17: =TEXT(O17, "mmmm") -> January | Q17: =ROUNDDOWN(YEARFRAC(O17, L17),0) -> 14 | R17: 0 | S17: =IF(R17=1, "Paid","Unpaid" ) -> Unpaid | T17: =IF(S17="Paid",B17, " ") | U17: =IF(S17="Unpaid",B17, " ") -> Martha Alexandra | V17: =VLOOKUP(A17,'Staff Salary'!A16:B117,2) -> 110 | W17: =IF(AND(TRIM(N17) = "M",TRIM(F17) ="USA"),V17*X17,0) -> 0 | X17: 0.2
A18: 16 | B18: =CONCATENATE(D18, " ",C18) -> Micah Allison | C18: Allison | D18: Micah | E18: 234 Hickman St. | F18: USA | G18: Springfield | H18: IL | I18: 27472 | J18: =ROUNDDOWN(YEARFRAC(I18,L18), 0) -> 50 | K18: =IF(J18<=30, "20-30",IF(J18<=40, "40-50",IF(J18<=50, "50-60",IF(J18<=60, "60-70",IF(J18<=70, "70-80",IF(J18<=80, "80-90")))))) -> 50-60 | L18: =TODAY() -> 45991 | M18: S | N18: M | O18: 39436 | P18: =TEXT(O18, "mmmm") -> December | Q18: =ROUNDDOWN(YEARFRAC(O18, L18),0) -> 17 | R18: 1 | S18: =IF(R18=1, "Paid","Unpaid" ) -> Paid | T18: =IF(S18="Paid",B18, " ") -> Micah Allison | U18: =IF(S18="Unpaid",B18, " ") | V18: =VLOOKUP(A18,'Staff Salary'!A17:B118,2) -> 120 | W18: =IF(AND(TRIM(N18) = "M",TRIM(F18) ="USA"),V18*X18,0) -> 24 | X18: 0.2
A19: 17 | B19: =CONCATENATE(D19, " ",C19) -> Omar Amanda | C19: Amanda | D19: Omar | E19: 98765 Crossway Park Dr | F19: USA | G19: Bloomington | H19: MN | I19: 31900 | J19: =ROUNDDOWN(YEARFRAC(I19,L19), 0) -> 38 | K19: =IF(J19<=30, "20-30",IF(J19<=40, "40-50",IF(J19<=50, "50-60",IF(J19<=60, "60-70",IF(J19<=70, "70-80",IF(J19<=80, "80-90")))))) -> 40-50 | L19: =TODAY() -> 45991 | M19: S | N19: M | O19: 39108 | P19: =TEXT(O19, "mmmm") -> January | Q19: =ROUNDDOWN(YEARFRAC(O19, L19),0) -> 18 | R19: 0 | S19: =IF(R19=1, "Paid","Unpaid" ) -> Unpaid | T19: =IF(S19="Paid",B19, " ") | U19: =IF(S19="Unpaid",B19, " ") -> Omar Amanda | V19: =VLOOKUP(A19,'Staff Salary'!A18:B119,2) -> 190 | W19: =IF(AND(TRIM(N19) = "M",TRIM(F19) ="USA"),V19*X19,0) -> 38 | X19: 0.2
A20: 18 | B20: =CONCATENATE(D20, " ",C20) -> Rafael Amber | C20: Amber | D20: Rafael | E20: 12345 21st Ave S | F20: USA | G20: Lawrence | H20: KS | I20: 28555 | J20: =ROUNDDOWN(YEARFRAC(I20,L20), 0) -> 47 | K20: =IF(J20<=30, "20-30",IF(J20<=40, "40-50",IF(J20<=50, "50-60",IF(J20<=60, "60-70",IF(J20<=70, "70-80",IF(J20<=80, "80-90")))))) -> 50-60 | L20: =TODAY() -> 45991 | M20: S | N20: M | O20: 40581 | P20: =TEXT(O20, "mmmm") -> February | Q20: =ROUNDDOWN(YEARFRAC(O20, L20),0) -> 14 | R20: 0 | S20: =IF(R20=1, "Paid","Unpaid" ) -> Unpaid | T20: =IF(S20="Paid",B20, " ") | U20: =IF(S20="Unpaid",B20, " ") -> Rafael Amber | V20: =VLOOKUP(A20,'Staff Salary'!A19:B120,2) -> 190 | W20: =IF(AND(TRIM(N20) = "M",TRIM(F20) ="USA"),V20*X20,0) -> 38 | X20: 0.2
A21: 19 | B21: =CONCATENATE(D21, " ",C21) -> Ramon Andrea | C21: Andrea | D21: Ramon | E21: 9876 N. Pioneer Road | F21: USA | G21: Gary | H21: IN | I21: 28519 | J21: =ROUNDDOWN(YEARFRAC(I21,L21), 0) -> 47 | K21: =IF(J21<=30, "20-30",IF(J21<=40, "40-50",IF(J21<=50, "50-60",IF(J21<=60, "60-70",IF(J21<=70, "70-80",IF(J21<=80, "80-90")))))) -> 50-60 | L21: =TODAY() -> 45991 | M21: S | N21: F | O21: 40588 | P21: =TEXT(O21, "mmmm") -> February | Q21: =ROUNDDOWN(YEARFRAC(O21, L21),0) -> 14 | R21: 0 | S21: =IF(R21=1, "Paid","Unpaid" ) -> Unpaid | T21: =IF(S21="Paid",B21, " ") | U21: =IF(S21="Unpaid",B21, " ") -> Ramon Andrea | V21: =VLOOKUP(A21,'Staff Salary'!A20:B121,2) -> 110 | W21: =IF(AND(TRIM(N21) = "M",TRIM(F21) ="USA"),V21*X21,0) -> 0 | X21: 0.2
A22: 20 | B22: =CONCATENATE(D22, " ",C22) -> Randy Angel | C22: Angel | D22: Randy | E22: 5678 Fraser Ave N. | F22: USA | G22: Mishawaka | H22: IN | I22: 27470 | J22: =ROUNDDOWN(YEARFRAC(I22,L22), 0) -> 50 | K22: =IF(J22<=30, "20-30",IF(J22<=40, "40-50",IF(J22<=50, "50-60",IF(J22<=60, "60-70",IF(J22<=70, "70-80",IF(J22<=80, "80-90")))))) -> 50-60 | L22: =TODAY() -> 45991 | M22: M | N22: F | O22: 40550 | P22: =TEXT(O22, "mmmm") -> January | Q22: =ROUNDDOWN(YEARFRAC(O22, L22),0) -> 14 | R22: 1 | S22: =IF(R22=1, "Paid","Unpaid" ) -> Paid | T22: =IF(S22="Paid",B22, " ") -> Randy Angel | U22: =IF(S22="Unpaid",B22, " ") | V22: =VLOOKUP(A22,'Staff Salary'!A21:B122,2) -> 190 | W22: =IF(AND(TRIM(N22) = "M",TRIM(F22) ="USA"),V22*X22,0) -> 0 | X22: 0.2
A23: 21 | B23: =CONCATENATE(D23, " ",C23) -> Roger Bailey | C23: Bailey | D23: Roger | E23: 1234 Sunlight Place | F23: USA | G23: Iowa City | H23: IA | I23: 31447 | J23: =ROUNDDOWN(YEARFRAC(I23,L23), 0) -> 39 | K23: =IF(J23<=30, "20-30",IF(J23<=40, "40-50",IF(J23<=50, "50-60",IF(J23<=60, "60-70",IF(J23<=70, "70-80",IF(J23<=80, "80-90")))))) -> 40-50 | L23: =TODAY() -> 45991 | M23: M | N23: M | O23: 39874 | P23: =TEXT(O23, "mmmm") -> March | Q23: =ROUNDDOWN(YEARFRAC(O23, L23),0) -> 16 | R23: 1 | S23: =IF(R23=1, "Paid","Unpaid" ) -> Paid | T23: =IF(S23="Paid",B23, " ") -> Roger Bailey | U23: =IF(S23="Unpaid",B23, " ") | V23: =VLOOKUP(A23,'Staff Salary'!A22:B123,2) -> 190 | W23: =IF(AND(TRIM(N23) = "M",TRIM(F23) ="USA"),V23*X23,0) -> 38 | X23: 0.2
A24: 22 | B24: =CONCATENATE(D24, " ",C24) -> Rosa Ben | C24: Ben | D24: Rosa | E24: 987 45 Ave. | F24: Canada | G24: Winnipeg | H24: MB | I24: 31918 | J24: =ROUNDDOWN(YEARFRAC(I24,L24), 0) -> 38 | K24: =IF(J24<=30, "20-30",IF(J24<=40, "40-50",IF(J24<=50, "50-60",IF(J24<=60, "60-70",IF(J24<=70, "70-80",IF(J24<=80, "80-90")))))) -> 40-50 | L24: =TODAY() -> 45991 | M24: S | N24: M | O24: 39794 | P24: =TEXT(O24, "mmmm") -> December | Q24: =ROUNDDOWN(YEARFRAC(O24, L24),0) -> 16 | R24: 1 | S24: =IF(R24=1, "Paid","Unpaid" ) -> Paid | T24: =IF(S24="Paid",B24, " ") -> Rosa Ben | U24: =IF(S24="Unpaid",B24, " ") | V24: =VLOOKUP(A24,'Staff Salary'!A23:B124,2) -> 225 | W24: =IF(AND(TRIM(N24) = "M",TRIM(F24) ="USA"),V24*X24,0) -> 0 | X24: 0.2
A25: 23 | B25: =CONCATENATE(D25, " ",C25) -> Sandra Blake | C25: Blake | D25: Sandra | E25: 4321 McDaniels Rd | F25: USA | G25: Minneapolis | H25: MN | I25: 22902 | J25: =ROUNDDOWN(YEARFRAC(I25,L25), 0) -> 63 | K25: =IF(J25<=30, "20-30",IF(J25<=40, "40-50",IF(J25<=50, "50-60",IF(J25<=60, "60-70",IF(J25<=70, "70-80",IF(J25<=80, "80-90")))))) -> 70-80 | L25: =TODAY() -> 45991 | M25: M | N25: F | O25: 39825 | P25: =TEXT(O25, "mmmm") -> January | Q25: =ROUNDDOWN(YEARFRAC(O25, L25),0) -> 16 | R25: 1 | S25: =IF(R25=1, "Paid","Unpaid" ) -> Paid | T25: =IF(S25="Paid",B25, " ") -> Sandra Blake | U25: =IF(S25="Unpaid",B25, " ") | V25: =VLOOKUP(A25,'Staff Salary'!A24:B125,2) -> 240 | W25: =IF(AND(TRIM(N25) = "M",TRIM(F25) ="USA"),V25*X25,0) -> 0 | X25: 0.2
... A65: 63 | B65: =CONCATENATE(D65, " ",C65) -> Gilbert Jose | C65: Jose | D65: Gilbert | E65: 432 12 Ave. North | F65: Canada | G65: Vancouver | H65: BC | I65: 20119 | J65: =ROUNDDOWN(YEARFRAC(I65,L65), 0) -> 70 | K65: =IF(J65<=30, "20-30",IF(J65<=40, "40-50",IF(J65<=50, "50-60",IF(J65<=60, "60-70",IF(J65<=70, "70-80",IF(J65<=80, "80-90")))))) -> 70-80 | L65: =TODAY() -> 45991 | M65: S | N65: M | O65: 40207 | P65: =TEXT(O65, "mmmm") -> January | Q65: =ROUNDDOWN(YEARFRAC(O65, L65),0) -> 15 | R65: 1 | S65: =IF(R65=1, "Paid","Unpaid" ) -> Paid | T65: =IF(S65="Paid",B65, " ") -> Gilbert Jose | U65: =IF(S65="Unpaid",B65, " ") | V65: =VLOOKUP(A65,'Staff Salary'!A64:B165,2) -> 190 | W65: =IF(AND(TRIM(N65) = "M",TRIM(F65) ="USA"),V65*X65,0) -> 0 | X65: 0.2
A66: 64 | B66: =CONCATENATE(D66, " ",C66) -> Glenn Julia | C66: Julia | D66: Glenn | E66: 123 Albert Ave | F66: New Zealand | G66: Palmerston North | I66: 26912 | J66: =ROUNDDOWN(YEARFRAC(I66,L66), 0) -> 52 | K66: =IF(J66<=30, "20-30",IF(J66<=40, "40-50",IF(J66<=50, "50-60",IF(J66<=60, "60-70",IF(J66<=70, "70-80",IF(J66<=80, "80-90")))))) -> 60-70 | L66: =TODAY() -> 45991 | M66: S | N66: M | O66: 40232 | P66: =TEXT(O66, "mmmm") -> February | Q66: =ROUNDDOWN(YEARFRAC(O66, L66),0) -> 15 | R66: 0 | S66: =IF(R66=1, "Paid","Unpaid" ) -> Unpaid | T66: =IF(S66="Paid",B66, " ") | U66: =IF(S66="Unpaid",B66, " ") -> Glenn Julia | V66: =VLOOKUP(A66,'Staff Salary'!A65:B166,2) -> 190 | W66: =IF(AND(TRIM(N66) = "M",TRIM(F66) ="USA"),V66*X66,0) -> 0 | X66: 0.2
A67: 65 | B67: =CONCATENATE(D67, " ",C67) -> Heather Kaitlyn | C67: Kaitlyn | D67: Heather | E67: 321 Park Drive | F67: USA | G67: Columbia | H67: MO | I67: 25686 | J67: =ROUNDDOWN(YEARFRAC(I67,L67), 0) -> 55 | K67: =IF(J67<=30, "20-30",IF(J67<=40, "40-50",IF(J67<=50, "50-60",IF(J67<=60, "60-70",IF(J67<=70, "70-80",IF(J67<=80, "80-90")))))) -> 60-70 | L67: =TODAY() -> 45991 | M67: M | N67: M | O67: 40232 | P67: =TEXT(O67, "mmmm") -> February | Q67: =ROUNDDOWN(YEARFRAC(O67, L67),0) -> 15 | R67: 0 | S67: =IF(R67=1, "Paid","Unpaid" ) -> Unpaid | T67: =IF(S67="Paid",B67, " ") | U67: =IF(S67="Unpaid",B67, " ") -> Heather Kaitlyn | V67: =VLOOKUP(A67,'Staff Salary'!A66:B167,2) -> 120 | W67: =IF(AND(TRIM(N67) = "M",TRIM(F67) ="USA"),V67*X67,0) -> 24 | X67: 0.2
A68: 66 | B68: =CONCATENATE(D68, " ",C68) -> Jaclyn Katelyn | C68: Katelyn | D68: Jaclyn | E68: 9876 Stevens Street | F68: USA | G68: Kansas City | H68: MO | I68: 25634 | J68: =ROUNDDOWN(YEARFRAC(I68,L68), 0) -> 55 | K68: =IF(J68<=30, "20-30",IF(J68<=40, "40-50",IF(J68<=50, "50-60",IF(J68<=60, "60-70",IF(J68<=70, "70-80",IF(J68<=80, "80-90")))))) -> 60-70 | L68: =TODAY() -> 45991 | M68: S | N68: M | O68: 40169 | P68: =TEXT(O68, "mmmm") -> December | Q68: =ROUNDDOWN(YEARFRAC(O68, L68),0) -> 15 | R68: 1 | S68: =IF(R68=1, "Paid","Unpaid" ) -> Paid | T68: =IF(S68="Paid",B68, " ") -> Jaclyn Katelyn | U68: =IF(S68="Unpaid",B68, " ") | V68: =VLOOKUP(A68,'Staff Salary'!A67:B168,2) -> 190 | W68: =IF(AND(TRIM(N68) = "M",TRIM(F68) ="USA"),V68*X68,0) -> 38 | X68: 0.2
A69: 67 | B69: =CONCATENATE(D69, " ",C69) -> Jake Katherine | C69: Katherine | D69: Jake | E69: 123 Sugar Grove | F69: USA | G69: Columbia | H69: MO | I69: 27801 | J69: =ROUNDDOWN(YEARFRAC(I69,L69), 0) -> 49 | K69: =IF(J69<=30, "20-30",IF(J69<=40, "40-50",IF(J69<=50, "50-60",IF(J69<=60, "60-70",IF(J69<=70, "70-80",IF(J69<=80, "80-90")))))) -> 50-60 | L69: =TODAY() -> 45991 | M69: S | N69: M | O69: 39877 | P69: =TEXT(O69, "mmmm") -> March | Q69: =ROUNDDOWN(YEARFRAC(O69, L69),0) -> 16 | R69: 0 | S69: =IF(R69=1, "Paid","Unpaid" ) -> Unpaid | T69: =IF(S69="Paid",B69, " ") | U69: =IF(S69="Unpaid",B69, " ") -> Jake Katherine | V69: =VLOOKUP(A69,'Staff Salary'!A68:B169,2) -> 190 | W69: =IF(AND(TRIM(N69) = "M",TRIM(F69) ="USA"),V69*X69,0) -> 38 | X69: 0.2
A70: 68 | B70: =CONCATENATE(D70, " ",C70) -> Jamie Kaylee | C70: Kaylee | D70: Jamie | E70: 456 19th Street S. | F70: USA | G70: Chicago | H70: IL | I70: 26178 | J70: =ROUNDDOWN(YEARFRAC(I70,L70), 0) -> 54 | K70: =IF(J70<=30, "20-30",IF(J70<=40, "40-50",IF(J70<=50, "50-60",IF(J70<=60, "60-70",IF(J70<=70, "70-80",IF(J70<=80, "80-90")))))) -> 60-70 | L70: =TODAY() -> 45991 | M70: S | N70: M | O70: 40150 | P70: =TEXT(O70, "mmmm") -> December | Q70: =ROUNDDOWN(YEARFRAC(O70, L70),0) -> 15 | R70: 1 | S70: =IF(R70=1, "Paid","Unpaid" ) -> Paid | T70: =IF(S70="Paid",B70, " ") -> Jamie Kaylee | U70: =IF(S70="Unpaid",B70, " ") | V70: =VLOOKUP(A70,'Staff Salary'!A69:B170,2) -> 190 | W70: =IF(AND(TRIM(N70) = "M",TRIM(F70) ="USA"),V70*X70,0) -> 38 | X70: 0.2
A71: 69 | B71: =CONCATENATE(D71, " ",C71) -> Jeffery Kevin | C71: Kevin | D71: Jeffery | E71: 8765 66 Ave. | F71: Canada | G71: Toronto | H71: ON | I71: 33334 | J71: =ROUNDDOWN(YEARFRAC(I71,L71), 0) -> 34 | K71: =IF(J71<=30, "20-30",IF(J71<=40, "40-50",IF(J71<=50, "50-60",IF(J71<=60, "60-70",IF(J71<=70, "70-80",IF(J71<=80, "80-90")))))) -> 40-50 | L71: =TODAY() -> 45991 | M71: S | N71: M | O71: 39859 | P71: =TEXT(O71, "mmmm") -> February | Q71: =ROUNDDOWN(YEARFRAC(O71, L71),0) -> 16 | R71: 0 | S71: =IF(R71=1, "Paid","Unpaid" ) -> Unpaid | T71: =IF(S71="Paid",B71, " ") | U71: =IF(S71="Unpaid",B71, " ") -> Jeffery Kevin | V71: =VLOOKUP(A71,'Staff Salary'!A70:B171,2) -> 190 | W71: =IF(AND(TRIM(N71) = "M",TRIM(F71) ="USA"),V71*X71,0) -> 0 | X71: 0.2
A72: 70 | B72: =CONCATENATE(D72, " ",C72) -> Jenny Kyle | C72: Kyle | D72: Jenny | E72: P.O. Box 3343 | F72: USA | G72: Detroit | H72: MI | I72: 31045 | J72: =ROUNDDOWN(YEARFRAC(I72,L72), 0) -> 40 | K72: =IF(J72<=30, "20-30",IF(J72<=40, "40-50",IF(J72<=50, "50-60",IF(J72<=60, "60-70",IF(J72<=70, "70-80",IF(J72<=80, "80-90")))))) -> 40-50 | L72: =TODAY() -> 45991 | M72: M | N72: M | O72: 39797 | P72: =TEXT(O72, "mmmm") -> December | Q72: =ROUNDDOWN(YEARFRAC(O72, L72),0) -> 16 | R72: 1 | S72: =IF(R72=1, "Paid","Unpaid" ) -> Paid | T72: =IF(S72="Paid",B72, " ") -> Jenny Kyle | U72: =IF(S72="Unpaid",B72, " ") | V72: =VLOOKUP(A72,'Staff Salary'!A71:B172,2) -> 610 | W72: =IF(AND(TRIM(N72) = "M",TRIM(F72) ="USA"),V72*X72,0) -> 122 | X72: 0.2
A73: 71 | B73: =CONCATENATE(D73, " ",C73) -> Jessie Logan | C73: Logan | D73: Jessie | E73: 123 Alfred St | F73: Australia | G73: Sydney | H73: NSW | I73: 32537 | J73: =ROUNDDOWN(YEARFRAC(I73,L73), 0) -> 36 | K73: =IF(J73<=30, "20-30",IF(J73<=40, "40-50",IF(J73<=50, "50-60",IF(J73<=60, "60-70",IF(J73<=70, "70-80",IF(J73<=80, "80-90")))))) -> 40-50 | L73: =TODAY() -> 45991 | M73: S | N73: M | O73: 39859 | P73: =TEXT(O73, "mmmm") -> February | Q73: =ROUNDDOWN(YEARFRAC(O73, L73),0) -> 16 | R73: 1 | S73: =IF(R73=1, "Paid","Unpaid" ) -> Paid | T73: =IF(S73="Paid",B73, " ") -> Jessie Logan | U73: =IF(S73="Unpaid",B73, " ") | V73: =VLOOKUP(A73,'Staff Salary'!A72:B173,2) -> 110 | W73: =IF(AND(TRIM(N73) = "M",TRIM(F73) ="USA"),V73*X73,0) -> 0 | X73: 0.2
A74: 72 | B74: =CONCATENATE(D74, " ",C74) -> Jon Lucas | C74: Lucas | D74: Jon | E74: 456 Sherwood Park South | F74: USA | G74: Arlington Heights | H74: IL | I74: 28259 | J74: =ROUNDDOWN(YEARFRAC(I74,L74), 0) -> 48 | K74: =IF(J74<=30, "20-30",IF(J74<=40, "40-50",IF(J74<=50, "50-60",IF(J74<=60, "60-70",IF(J74<=70, "70-80",IF(J74<=80, "80-90")))))) -> 50-60 | L74: =TODAY() -> 45991 | M74: M | N74: M | O74: 39783 | P74: =TEXT(O74, "mmmm") -> December | Q74: =ROUNDDOWN(YEARFRAC(O74, L74),0) -> 16 | R74: 1 | S74: =IF(R74=1, "Paid","Unpaid" ) -> Paid | T74: =IF(S74="Paid",B74, " ") -> Jon Lucas | U74: =IF(S74="Unpaid",B74, " ") | V74: =VLOOKUP(A74,'Staff Salary'!A73:B174,2) -> 190 | W74: =IF(AND(TRIM(N74) = "M",TRIM(F74) ="USA"),V74*X74,0) -> 38 | X74: 0.2
A75: 73 | B75: =CONCATENATE(D75, " ",C75) -> Jorge Luis | C75: Luis | D75: Jorge | E75: 321 Garden Mall | F75: USA | G75: Lincoln | H75: NE | I75: 30608 | J75: =ROUNDDOWN(YEARFRAC(I75,L75), 0) -> 42 | K75: =IF(J75<=30, "20-30",IF(J75<=40, "40-50",IF(J75<=50, "50-60",IF(J75<=60, "60-70",IF(J75<=70, "70-80",IF(J75<=80, "80-90")))))) -> 50-60 | L75: =TODAY() -> 45991 | M75: M | N75: F | O75: 39801 | P75: =TEXT(O75, "mmmm") -> December | Q75: =ROUNDDOWN(YEARFRAC(O75, L75),0) -> 16 | R75: 0 | S75: =IF(R75=1, "Paid","Unpaid" ) -> Unpaid | T75: =IF(S75="Paid",B75, " ") | U75: =IF(S75="Unpaid",B75, " ") -> Jorge Luis | V75: =VLOOKUP(A75,'Staff Salary'!A74:B175,2) -> 120 | W75: =IF(AND(TRIM(N75) = "M",TRIM(F75) ="USA"),V75*X75,0) -> 0 | X75: 0.2
A76: 74 | B76: =CONCATENATE(D76, " ",C76) -> Karen Luke | C76: Luke | D76: Karen | E76: 987 West Alaska Ave | F76: USA | G76: Gary | H76: IN | I76: 32818 | J76: =ROUNDDOWN(YEARFRAC(I76,L76), 0) -> 36 | K76: =IF(J76<=30, "20-30",IF(J76<=40, "40-50",IF(J76<=50, "50-60",IF(J76<=60, "60-70",IF(J76<=70, "70-80",IF(J76<=80, "80-90")))))) -> 40-50 | L76: =TODAY() -> 45991 | M76: S | N76: M | O76: 39820 | P76: =TEXT(O76, "mmmm") -> January | Q76: =ROUNDDOWN(YEARFRAC(O76, L76),0) -> 16 | R76: 0 | S76: =IF(R76=1, "Paid","Unpaid" ) -> Unpaid | T76: =IF(S76="Paid",B76, " ") | U76: =IF(S76="Unpaid",B76, " ") -> Karen Luke | V76: =VLOOKUP(A76,'Staff Salary'!A75:B176,2) -> 190 | W76: =IF(AND(TRIM(N76) = "M",TRIM(F76) ="USA"),V76*X76,0) -> 38 | X76: 0.2
A77: 75 | B77: =CONCATENATE(D77, " ",C77) -> Kelli Mackenzie | C77: Mackenzie | D77: Kelli | E77: 567 W 7th St. | F77: USA | G77: Bloomington | H77: IL | I77: 30129 | J77: =ROUNDDOWN(YEARFRAC(I77,L77), 0) -> 43 | K77: =IF(J77<=30, "20-30",IF(J77<=40, "40-50",IF(J77<=50, "50-60",IF(J77<=60, "60-70",IF(J77<=70, "70-80",IF(J77<=80, "80-90")))))) -> 50-60 | L77: =TODAY() -> 45991 | M77: S | N77: M | O77: 39839 | P77: =TEXT(O77, "mmmm") -> January | Q77: =ROUNDDOWN(YEARFRAC(O77, L77),0) -> 16 | R77: 0 | S77: =IF(R77=1, "Paid","Unpaid" ) -> Unpaid | T77: =IF(S77="Paid",B77, " ") | U77: =IF(S77="Unpaid",B77, " ") -> Kelli Mackenzie | V77: =VLOOKUP(A77,'Staff Salary'!A76:B177,2) -> 120 | W77: =IF(AND(TRIM(N77) = "M",TRIM(F77) ="USA"),V77*X77,0) -> 24 | X77: 0.2
A78: 76 | B78: =CONCATENATE(D78, " ",C78) -> Kelvin Marcus | C78: Marcus | D78: Kelvin | E78: One Microsoft Way | F78: USA | G78: Redmond | H78: WA | I78: 32433 | J78: =ROUNDDOWN(YEARFRAC(I78,L78), 0) -> 37 | K78: =IF(J78<=30, "20-30",IF(J78<=40, "40-50",IF(J78<=50, "50-60",IF(J78<=60, "60-70",IF(J78<=70, "70-80",IF(J78<=80, "80-90")))))) -> 40-50 | L78: =TODAY() -> 45991 | M78: M | N78: F | O78: 39856 | P78: =TEXT(O78, "mmmm") -> February | Q78: =ROUNDDOWN(YEARFRAC(O78, L78),0) -> 16 | R78: 1 | S78: =IF(R78=1, "Paid","Unpaid" ) -> Paid | T78: =IF(S78="Paid",B78, " ") -> Kelvin Marcus | U78: =IF(S78="Unpaid",B78, " ") | V78: =VLOOKUP(A78,'Staff Salary'!A77:B178,2) -> 120 | W78: =IF(AND(TRIM(N78) = "M",TRIM(F78) ="USA"),V78*X78,0) -> 0 | X78: 0.2
... A104: 102 | B104: =CONCATENATE(D104, " ",C104) -> Willie Robert | C104: Robert | D104: Willie | E104: 9876 Bernard St. | F104: Canada | G104: Edmonton | H104: AB | I104: 30615 | J104: =ROUNDDOWN(YEARFRAC(I104,L104), 0) -> 42 | K104: =IF(J104<=30, "20-30",IF(J104<=40, "40-50",IF(J104<=50, "50-60",IF(J104<=60, "60-70",IF(J104<=70, "70-80",IF(J104<=80, "80-90")))))) -> 50-60 | L104: =TODAY() -> 45991 | M104: S | N104: M | O104: 39785 | P104: =TEXT(O104, "mmmm") -> December | Q104: =ROUNDDOWN(YEARFRAC(O104, L104),0) -> 16 | R104: 0 | S104: =IF(R104=1, "Paid","Unpaid" ) -> Unpaid | T104: =IF(S104="Paid",B104, " ") | U104: =IF(S104="Unpaid",B104, " ") -> Willie Robert | V104: =VLOOKUP(A104,'Staff Salary'!A103:B204,2) -> 610 | W104: =IF(AND(TRIM(N104) = "M",TRIM(F104) ="USA"),V104*X104,0) -> 0 | X104: 0.2

Sheet Staff Salary
A1: StaffID | B1: Salary
A2: 1 | B2: 120
A3: 2 | B3: 190
A4: 3 | B4: 120
A5: 4 | B5: 190
A6: 5 | B6: 610
A7: 6 | B7: 120
A8: 7 | B8: 120
A9: 8 | B9: 360
A10: 9 | B10: 190
A11: 10 | B11: 190
A12: 11 | B12: 190
A13: 12 | B13: 610
... A103: 102 | B103: 610
